<?xml version="1.0" encoding="utf-8"?>
<!-- This URDF was automatically created by SolidWorks to URDF Exporter! Originally created by Stephen Brawner (brawner@gmail.com) 
     Commit Version: 1.6.0-4-g7f85cfe  Build Version: 1.6.7995.38578
     For more information, please see http://wiki.ros.org/sw_urdf_exporter -->
<robot
  name="250226_DummyBipedURDF">
  <link
    name="base_link">
    <inertial>
      <origin
        xyz="-5.1038E-08 5.4326E-06 0.95377"
        rpy="0 0 0" />
      <mass
        value="6.4875" />
      <inertia
        ixx="0.013251"
        ixy="-1.0594E-07"
        ixz="1.1747E-08"
        iyy="0.018788"
        iyz="-2.0057E-07"
        izz="0.016546" />
    </inertial>
    <visual>
      <origin
        xyz="0 0 0"
        rpy="0 0 0" />
      <geometry>
        <mesh
          filename="../meshes/base_link.STL" />
      </geometry>
      <material
        name="">
        <color
          rgba="0.89804 0.91765 0.92941 1" />
      </material>
    </visual>
    <collision>
      <origin
        xyz="0 0 0"
        rpy="0 0 0" />
      <geometry>
        <mesh
          filename="../meshes/base_link.STL" />
      </geometry>
    </collision>
  </link>
  <link
    name="Torso_Yaw_Link">
    <inertial>
      <origin
        xyz="1.1997E-17 0.054131 -2.8977E-17"
        rpy="0 0 0" />
      <mass
        value="1.9589" />
      <inertia
        ixx="0.0020305"
        ixy="-7.9398E-19"
        ixz="-5.6399E-10"
        iyy="0.0022686"
        iyz="1.8408E-18"
        izz="0.0026768" />
    </inertial>
    <visual>
      <origin
        xyz="0 0 0"
        rpy="0 0 0" />
      <geometry>
        <mesh
          filename="../meshes/Torso_Yaw_Link.STL" />
      </geometry>
      <material
        name="">
        <color
          rgba="0.89804 0.91765 0.92941 1" />
      </material>
    </visual>
    <collision>
      <origin
        xyz="0 0 0"
        rpy="0 0 0" />
      <geometry>
        <mesh
          filename="../meshes/Torso_Yaw_Link.STL" />
      </geometry>
    </collision>
  </link>
  <joint
    name="Torso_Yaw"
    type="revolute">
    <origin
      xyz="0 0 1.045"
      rpy="1.5708 0 0" />
    <parent
      link="base_link" />
    <child
      link="Torso_Yaw_Link" />
    <axis
      xyz="0 1 0" />
    <limit
      lower="-1.5707"
      upper="1.5707"
      effort="0"
      velocity="0" />
  </joint>
  <link
    name="Torso_AA_Link">
    <inertial>
      <origin
        xyz="-2.0708E-07 0.22736 -0.0095751"
        rpy="0 0 0" />
      <mass
        value="30" />
      <inertia
        ixx="0.12796"
        ixy="3.2398E-07"
        ixz="-2.8027E-08"
        iyy="0.10181"
        iyz="0.0058619"
        izz="0.12906" />
    </inertial>
    <visual>
      <origin
        xyz="0 0 0"
        rpy="0 0 0" />
      <geometry>
        <mesh
          filename="../meshes/Torso_AA_Link.STL" />
      </geometry>
      <material
        name="">
        <color
          rgba="0.89804 0.91765 0.92941 1" />
      </material>
    </visual>
    <collision>
      <origin
        xyz="0 0 0"
        rpy="0 0 0" />
      <geometry>
        <mesh
          filename="../meshes/Torso_AA_Link.STL" />
      </geometry>
    </collision>
  </link>
  <joint
    name="Torso_AA"
    type="revolute">
    <origin
      xyz="0 0.0800000000000003 0"
      rpy="0 0 0" />
    <parent
      link="Torso_Yaw_Link" />
    <child
      link="Torso_AA_Link" />
    <axis
      xyz="0 0 1" />
    <limit
      lower="-0.785"
      upper="0.785"
      effort="0"
      velocity="0" />
  </joint>
  <link
    name="Neck_Yaw_Link">
    <inertial>
      <origin
        xyz="-1.4038E-08 0.029123 3.699E-09"
        rpy="0 0 0" />
      <mass
        value="0.45918" />
      <inertia
        ixx="0.00025102"
        ixy="-1.3964E-10"
        ixz="1.1085E-10"
        iyy="0.00027253"
        iyz="-1.7767E-11"
        izz="0.00024693" />
    </inertial>
    <visual>
      <origin
        xyz="0 0 0"
        rpy="0 0 0" />
      <geometry>
        <mesh
          filename="../meshes/Neck_Yaw_Link.STL" />
      </geometry>
      <material
        name="">
        <color
          rgba="0.89804 0.91765 0.92941 1" />
      </material>
    </visual>
    <collision>
      <origin
        xyz="0 0 0"
        rpy="0 0 0" />
      <geometry>
        <mesh
          filename="../meshes/Neck_Yaw_Link.STL" />
      </geometry>
    </collision>
  </link>
  <joint
    name="Neck_Yaw"
    type="revolute">
    <origin
      xyz="0 0.355 -0.0129866470414555"
      rpy="0 0 0" />
    <parent
      link="Torso_AA_Link" />
    <child
      link="Neck_Yaw_Link" />
    <axis
      xyz="0 1 0" />
    <limit
      lower="-0.785"
      upper="0.785"
      effort="0"
      velocity="0" />
  </joint>
  <link
    name="Neck_FE_Link">
    <inertial>
      <origin
        xyz="2.2453E-06 0.15386 0.035067"
        rpy="0 0 0" />
      <mass
        value="3" />
      <inertia
        ixx="0.04359"
        ixy="-3.1398E-07"
        ixz="-1.9196E-07"
        iyy="0.023367"
        iyz="0.0026283"
        izz="0.047363" />
    </inertial>
    <visual>
      <origin
        xyz="0 0 0"
        rpy="0 0 0" />
      <geometry>
        <mesh
          filename="../meshes/Neck_FE_Link.STL" />
      </geometry>
      <material
        name="">
        <color
          rgba="0.89804 0.91765 0.92941 1" />
      </material>
    </visual>
    <collision>
      <origin
        xyz="0 0 0"
        rpy="0 0 0" />
      <geometry>
        <mesh
          filename="../meshes/Neck_FE_Link.STL" />
      </geometry>
    </collision>
  </link>
  <joint
    name="Neck_FE"
    type="revolute">
    <origin
      xyz="0 0.0399999999999998 0"
      rpy="0 0 0" />
    <parent
      link="Neck_Yaw_Link" />
    <child
      link="Neck_FE_Link" />
    <axis
      xyz="1 0 0" />
    <limit
      lower="-0.785"
      upper="0.785"
      effort="0"
      velocity="0" />
  </joint>
  <link
    name="Shoulder_FE_R_Link">
    <inertial>
      <origin
        xyz="-0.0310067505083414 0.019345596761579 1.48881177824227E-10"
        rpy="0 0 0" />
      <mass
        value="1.80654252567583" />
      <inertia
        ixx="0.00223136805713306"
        ixy="0.000243223757907872"
        ixz="-2.90423444678987E-10"
        iyy="0.00246945115474458"
        iyz="-4.63576699028405E-10"
        izz="0.00270170721323667" />
    </inertial>
    <visual>
      <origin
        xyz="0 0 0"
        rpy="0 0 0" />
      <geometry>
        <mesh
          filename="../meshes/Shoulder_FE_R_Link.STL" />
      </geometry>
      <material
        name="">
        <color
          rgba="0.898039215686275 0.917647058823529 0.929411764705882 1" />
      </material>
    </visual>
    <collision>
      <origin
        xyz="0 0 0"
        rpy="0 0 0" />
      <geometry>
        <mesh
          filename="../meshes/Shoulder_FE_R_Link.STL" />
      </geometry>
    </collision>
  </link>
  <joint
    name="Shoulder_FE_R"
    type="revolute">
    <origin
      xyz="-0.134606791294279 0.313081203127166 0"
      rpy="0 0 0" />
    <parent
      link="Torso_AA_Link" />
    <child
      link="Shoulder_FE_R_Link" />
    <axis
      xyz="0.848411485673513 -0.529337275257715 0" />
    <limit
      lower="-0.785"
      upper="3.141"
      effort="0"
      velocity="0" />
  </joint>
  <link
    name="Shoulder_AA_R_Link">
    <inertial>
      <origin
        xyz="-0.0381306595274215 -0.0834509868200322 -0.0151840043629273"
        rpy="0 0 0" />
      <mass
        value="1.247855047949" />
      <inertia
        ixx="0.00255619066796935"
        ixy="-0.000745614459901058"
        ixz="0.000210043728183181"
        iyy="0.0012650690077835"
        iyz="0.000459692806544922"
        izz="0.00280837799737988" />
    </inertial>
    <visual>
      <origin
        xyz="0 0 0"
        rpy="0 0 0" />
      <geometry>
        <mesh
          filename="../meshes/Shoulder_AA_R_Link.STL" />
      </geometry>
      <material
        name="">
        <color
          rgba="0.898039215686275 0.917647058823529 0.929411764705882 1" />
      </material>
    </visual>
    <collision>
      <origin
        xyz="0 0 0"
        rpy="0 0 0" />
      <geometry>
        <mesh
          filename="../meshes/Shoulder_AA_R_Link.STL" />
      </geometry>
    </collision>
  </link>
  <joint
    name="Shoulder_AA_R"
    type="revolute">
    <origin
      xyz="-0.0496017470231125 0.0309473104273139 0"
      rpy="0 0 0" />
    <parent
      link="Shoulder_FE_R_Link" />
    <child
      link="Shoulder_AA_R_Link" />
    <axis
      xyz="0 0 1" />
    <limit
      lower="-0.785"
      upper="2.094"
      effort="0"
      velocity="0" />
  </joint>
  <link
    name="Shoulder_Yaw_R_Link">
    <inertial>
      <origin
        xyz="-0.0519770780045243 -0.113754803821021 2.1573737799135E-09"
        rpy="0 0 0" />
      <mass
        value="2.06319971291781" />
      <inertia
        ixx="0.00360586911977551"
        ixy="-0.000803766521239213"
        ixz="-0.00015613227592812"
        iyy="0.00221403833441209"
        iyz="7.13399292874001E-05"
        izz="0.00432891643180672" />
    </inertial>
    <visual>
      <origin
        xyz="0 0 0"
        rpy="0 0 0" />
      <geometry>
        <mesh
          filename="../meshes/Shoulder_Yaw_R_Link.STL" />
      </geometry>
      <material
        name="">
        <color
          rgba="0.898039215686275 0.917647058823529 0.929411764705882 1" />
      </material>
    </visual>
    <collision>
      <origin
        xyz="0 0 0"
        rpy="0 0 0" />
      <geometry>
        <mesh
          filename="../meshes/Shoulder_Yaw_R_Link.STL" />
      </geometry>
    </collision>
  </link>
  <joint
    name="Shoulder_Yaw_R"
    type="revolute">
    <origin
      xyz="-0.0516249564943227 -0.112984177257028 0"
      rpy="0 0 0" />
    <parent
      link="Shoulder_AA_R_Link" />
    <child
      link="Shoulder_Yaw_R_Link" />
    <axis
      xyz="0.415593597783362 0.909550417229018 0" />
    <limit
      lower="-1.57"
      upper="1.57"
      effort="0"
      velocity="0" />
  </joint>
  <link
    name="Elbow_FE_R_Link">
    <inertial>
      <origin
        xyz="-0.0430905861287604 -0.0545416277452424 0.00455317320276115"
        rpy="0 0 0" />
      <mass
        value="0.692088336953301" />
      <inertia
        ixx="0.000881635924536338"
        ixy="-5.45477026515835E-05"
        ixz="2.15374708302045E-05"
        iyy="0.000351801344105622"
        iyz="0.000148361087401981"
        izz="0.000826885225838731" />
    </inertial>
    <visual>
      <origin
        xyz="0 0 0"
        rpy="0 0 0" />
      <geometry>
        <mesh
          filename="../meshes/Elbow_FE_R_Link.STL" />
      </geometry>
      <material
        name="">
        <color
          rgba="0.898039215686275 0.917647058823529 0.929411764705882 1" />
      </material>
    </visual>
    <collision>
      <origin
        xyz="0 0 0"
        rpy="0 0 0" />
      <geometry>
        <mesh
          filename="../meshes/Elbow_FE_R_Link.STL" />
      </geometry>
    </collision>
  </link>
  <joint
    name="Elbow_FE_R"
    type="revolute">
    <origin
      xyz="-0.0748034856878404 -0.163711717361511 0"
      rpy="0 0 0" />
    <parent
      link="Shoulder_Yaw_R_Link" />
    <child
      link="Elbow_FE_R_Link" />
    <axis
      xyz="0.843385849793954 -0.385361551153234 0.374428609029951" />
    <limit
      lower="-0.157"
      upper="2.268"
      effort="0"
      velocity="0" />
  </joint>
  <link
    name="Elbow_Yaw_R_Link">
    <inertial>
      <origin
        xyz="-0.0300774802367351 -0.0569008247691511 0.00918608157764246"
        rpy="0 0 0" />
      <mass
        value="0.486444545942294" />
      <inertia
        ixx="0.000207124470524885"
        ixy="-9.88793102363349E-06"
        ixz="-1.73468963111058E-05"
        iyy="0.000202259244154704"
        iyz="2.05411115364028E-05"
        izz="0.000264155161494633" />
    </inertial>
    <visual>
      <origin
        xyz="0 0 0"
        rpy="0 0 0" />
      <geometry>
        <mesh
          filename="../meshes/Elbow_Yaw_R_Link.STL" />
      </geometry>
      <material
        name="">
        <color
          rgba="0.898039215686275 0.917647058823529 0.929411764705882 1" />
      </material>
    </visual>
    <collision>
      <origin
        xyz="0 0 0"
        rpy="0 0 0" />
      <geometry>
        <mesh
          filename="../meshes/Elbow_Yaw_R_Link.STL" />
      </geometry>
    </collision>
  </link>
  <joint
    name="Elbow_Yaw_R"
    type="revolute">
    <origin
      xyz="-0.042145521469758 -0.0797312447084886 0.0128718270647735"
      rpy="0 0 0" />
    <parent
      link="Elbow_FE_R_Link" />
    <child
      link="Elbow_Yaw_R_Link" />
    <axis
      xyz="0.462635059808256 0.875216817302152 -0.141295166752804" />
    <limit
      lower="-1.57"
      upper="1.57"
      effort="0"
      velocity="0" />
  </joint>
  <link
    name="Wrist_FE_R_Link">
    <inertial>
      <origin
        xyz="-0.0340290841582708 -0.0639823677206759 0.0102672042908063"
        rpy="0 0 0" />
      <mass
        value="0.456187504829232" />
      <inertia
        ixx="0.000374944464779548"
        ixy="-8.42596042439924E-05"
        ixz="4.1303230793248E-05"
        iyy="0.000247484306552816"
        iyz="1.13021461676669E-07"
        izz="0.000338863870451295" />
    </inertial>
    <visual>
      <origin
        xyz="0 0 0"
        rpy="0 0 0" />
      <geometry>
        <mesh
          filename="../meshes/Wrist_FE_R_Link.STL" />
      </geometry>
      <material
        name="">
        <color
          rgba="0.898039215686275 0.917647058823529 0.929411764705882 1" />
      </material>
    </visual>
    <collision>
      <origin
        xyz="0 0 0"
        rpy="0 0 0" />
      <geometry>
        <mesh
          filename="../meshes/Wrist_FE_R_Link.STL" />
      </geometry>
    </collision>
  </link>
  <joint
    name="Wrist_FE_R"
    type="revolute">
    <origin
      xyz="-0.0371487302648139 -0.0702782739437464 0.0113457376957058"
      rpy="0 0 0" />
    <parent
      link="Elbow_Yaw_R_Link" />
    <child
      link="Wrist_FE_R_Link" />
    <axis
      xyz="0.273256490871751 -0.292390146216084 -0.916427243479914" />
    <limit
      lower="-0.785"
      upper="0.785"
      effort="0"
      velocity="0" />
  </joint>
  <link
    name="Wrist_AA_R_Link">
    <inertial>
      <origin
        xyz="-0.048154488130251 -0.0885984034333783 0.0118552801837085"
        rpy="0 0 0" />
      <mass
        value="1.16298779128614" />
      <inertia
        ixx="0.00278615991733156"
        ixy="-0.000655299883896485"
        ixz="-4.65557798434695E-05"
        iyy="0.00150110022156653"
        iyz="5.6827481544962E-05"
        izz="0.00243448126996028" />
    </inertial>
    <visual>
      <origin
        xyz="0 0 0"
        rpy="0 0 0" />
      <geometry>
        <mesh
          filename="../meshes/Wrist_AA_R_Link.STL" />
      </geometry>
      <material
        name="">
        <color
          rgba="0.898039215686275 0.917647058823529 0.929411764705882 1" />
      </material>
    </visual>
    <collision>
      <origin
        xyz="0 0 0"
        rpy="0 0 0" />
      <geometry>
        <mesh
          filename="../meshes/Wrist_AA_R_Link.STL" />
      </geometry>
    </collision>
  </link>
  <joint
    name="Wrist_AA_R"
    type="revolute">
    <origin
      xyz="-0.0439503306817846 -0.0831455976437052 0.0134230408415164"
      rpy="0 0 0" />
    <parent
      link="Wrist_FE_R_Link" />
    <child
      link="Wrist_AA_R_Link" />
    <axis
      xyz="0.843385849793954 -0.385361551153234 0.374428609029951" />
    <limit
      lower="-0.785"
      upper="0.785"
      effort="0"
      velocity="0" />
  </joint>
  <link
    name="Shoulder_FE_L_Link">
    <inertial>
      <origin
        xyz="0.0911899084281182 0.0568948159407252 1.48881252208518E-10"
        rpy="0 0 0" />
      <mass
        value="1.80654252567583" />
      <inertia
        ixx="0.0022313680571334"
        ixy="-0.000243223757908136"
        ixz="2.90423441848133E-10"
        iyy="0.00246945115474501"
        iyz="-4.6357669813026E-10"
        izz="0.00270170721323742" />
    </inertial>
    <visual>
      <origin
        xyz="0 0 0"
        rpy="0 0 0" />
      <geometry>
        <mesh
          filename="../meshes/Shoulder_FE_L_Link.STL" />
      </geometry>
      <material
        name="">
        <color
          rgba="0.898039215686275 0.917647058823529 0.929411764705882 1" />
      </material>
    </visual>
    <collision>
      <origin
        xyz="0 0 0"
        rpy="0 0 0" />
      <geometry>
        <mesh
          filename="../meshes/Shoulder_FE_L_Link.STL" />
      </geometry>
    </collision>
  </link>
  <joint
    name="Shoulder_FE_L"
    type="revolute">
    <origin
      xyz="0.0744236333745026 0.275531983948021 0"
      rpy="0 0 0" />
    <parent
      link="Torso_AA_Link" />
    <child
      link="Shoulder_FE_L_Link" />
    <axis
      xyz="0.848411485673513 0.529337275257715 0" />
    <limit
      lower="-0.785"
      upper="3.141"
      effort="0"
      velocity="0" />
  </joint>
  <link
    name="Shoulder_AA_L_Link">
    <inertial>
      <origin
        xyz="0.0381306914977411 -0.0834510282291694 -0.0151840384829405"
        rpy="0 0 0" />
      <mass
        value="1.24785803890815" />
      <inertia
        ixx="0.00255619297670402"
        ixy="0.00074561597091883"
        ixz="-0.000210043630275466"
        iyy="0.00126506988452807"
        iyz="0.000459692606514037"
        izz="0.00280838097149953" />
    </inertial>
    <visual>
      <origin
        xyz="0 0 0"
        rpy="0 0 0" />
      <geometry>
        <mesh
          filename="../meshes/Shoulder_AA_L_Link.STL" />
      </geometry>
      <material
        name="">
        <color
          rgba="0.898039215686275 0.917647058823529 0.929411764705882 1" />
      </material>
    </visual>
    <collision>
      <origin
        xyz="0 0 0"
        rpy="0 0 0" />
      <geometry>
        <mesh
          filename="../meshes/Shoulder_AA_L_Link.STL" />
      </geometry>
    </collision>
  </link>
  <joint
    name="Shoulder_AA_L"
    type="revolute">
    <origin
      xyz="0.109784904942889 0.0684965296064597 0"
      rpy="0 0 0" />
    <parent
      link="Shoulder_FE_L_Link" />
    <child
      link="Shoulder_AA_L_Link" />
    <axis
      xyz="0 0 1" />
    <limit
      lower="-0.785"
      upper="2.094"
      effort="0"
      velocity="0" />
  </joint>
  <link
    name="Shoulder_Yaw_L_Link">
    <inertial>
      <origin
        xyz="0.0259050715631457 -0.056694727569738 5.37980859727346E-09"
        rpy="0 0 0" />
      <mass
        value="2.0632030388164" />
      <inertia
        ixx="0.00360586913325862"
        ixy="0.000803766571522294"
        ixz="0.000156132362757545"
        iyy="0.00221403832568276"
        iyz="7.13400283581453E-05"
        izz="0.00432891589749316" />
    </inertial>
    <visual>
      <origin
        xyz="0 0 0"
        rpy="0 0 0" />
      <geometry>
        <mesh
          filename="../meshes/Shoulder_Yaw_L_Link.STL" />
      </geometry>
      <material
        name="">
        <color
          rgba="0.898039215686275 0.917647058823529 0.929411764705882 1" />
      </material>
    </visual>
    <collision>
      <origin
        xyz="0 0 0"
        rpy="0 0 0" />
      <geometry>
        <mesh
          filename="../meshes/Shoulder_Yaw_L_Link.STL" />
      </geometry>
    </collision>
  </link>
  <joint
    name="Shoulder_Yaw_L"
    type="revolute">
    <origin
      xyz="0.0776969434403317 -0.170044215552164 0"
      rpy="0 0 0" />
    <parent
      link="Shoulder_AA_L_Link" />
    <child
      link="Shoulder_Yaw_L_Link" />
    <axis
      xyz="0.415593597783362 -0.909550417229018 0" />
    <limit
      lower="-1.57"
      upper="1.57"
      effort="0"
      velocity="0" />
  </joint>
  <link
    name="Elbow_FE_L_Link">
    <inertial>
      <origin
        xyz="0.0430905166465817 -0.0545417440406633 0.00455283445937587"
        rpy="0 0 0" />
      <mass
        value="0.692089248900635" />
      <inertia
        ixx="0.000881654485049893"
        ixy="5.45506410031268E-05"
        ixz="-2.15275099931176E-05"
        iyy="0.000351807624276591"
        iyz="0.000148354489673587"
        izz="0.000826883425114298" />
    </inertial>
    <visual>
      <origin
        xyz="0 0 0"
        rpy="0 0 0" />
      <geometry>
        <mesh
          filename="../meshes/Elbow_FE_L_Link.STL" />
      </geometry>
      <material
        name="">
        <color
          rgba="0.898039215686275 0.917647058823529 0.929411764705882 1" />
      </material>
    </visual>
    <collision>
      <origin
        xyz="0 0 0"
        rpy="0 0 0" />
      <geometry>
        <mesh
          filename="../meshes/Elbow_FE_L_Link.STL" />
      </geometry>
    </collision>
  </link>
  <joint
    name="Elbow_FE_L"
    type="revolute">
    <origin
      xyz="0.0487314987418315 -0.106651679066375 0"
      rpy="0 0 0" />
    <parent
      link="Shoulder_Yaw_L_Link" />
    <child
      link="Elbow_FE_L_Link" />
    <axis
      xyz="0.843385849793954 0.385361551153234 -0.374428609029951" />
    <limit
      lower="-0.157"
      upper="2.268"
      effort="0"
      velocity="0" />
  </joint>
  <link
    name="Elbow_Yaw_L_Link">
    <inertial>
      <origin
        xyz="0.0109040945189667 -0.0206284552933813 0.00333026398901495"
        rpy="0 0 0" />
      <mass
        value="0.486444532765781" />
      <inertia
        ixx="0.000207124461896542"
        ixy="9.88793027126458E-06"
        ixz="1.73469000994959E-05"
        iyy="0.000202259233711323"
        iyz="2.05411093239393E-05"
        izz="0.000264155157374209" />
    </inertial>
    <visual>
      <origin
        xyz="0 0 0"
        rpy="0 0 0" />
      <geometry>
        <mesh
          filename="../meshes/Elbow_Yaw_L_Link.STL" />
      </geometry>
      <material
        name="">
        <color
          rgba="0.898039215686275 0.917647058823529 0.929411764705882 1" />
      </material>
    </visual>
    <collision>
      <origin
        xyz="0 0 0"
        rpy="0 0 0" />
      <geometry>
        <mesh
          filename="../meshes/Elbow_Yaw_L_Link.STL" />
      </geometry>
    </collision>
  </link>
  <joint
    name="Elbow_Yaw_L"
    type="revolute">
    <origin
      xyz="0.0613189078897877 -0.116003615086985 0.0187276453258385"
      rpy="0 0 0" />
    <parent
      link="Elbow_FE_L_Link" />
    <child
      link="Elbow_Yaw_L_Link" />
    <axis
      xyz="0.462635059808256 -0.875216817302152 0.141295166752804" />
    <limit
      lower="-1.57"
      upper="1.57"
      effort="0"
      velocity="0" />
  </joint>
  <link
    name="Wrist_FE_L_Link">
    <inertial>
      <origin
        xyz="0.0340290841582708 -0.0639823677206758 0.0102672042908063"
        rpy="0 0 0" />
      <mass
        value="0.456187504829231" />
      <inertia
        ixx="0.000374944464779554"
        ixy="8.42596042439878E-05"
        ixz="-4.13032307932444E-05"
        iyy="0.000247484306552825"
        iyz="1.13021461679485E-07"
        izz="0.000338863870451307" />
    </inertial>
    <visual>
      <origin
        xyz="0 0 0"
        rpy="0 0 0" />
      <geometry>
        <mesh
          filename="../meshes/Wrist_FE_L_Link.STL" />
      </geometry>
      <material
        name="">
        <color
          rgba="0.898039215686275 0.917647058823529 0.929411764705882 1" />
      </material>
    </visual>
    <collision>
      <origin
        xyz="0 0 0"
        rpy="0 0 0" />
      <geometry>
        <mesh
          filename="../meshes/Wrist_FE_L_Link.STL" />
      </geometry>
    </collision>
  </link>
  <joint
    name="Wrist_FE_L"
    type="revolute">
    <origin
      xyz="0.0179753438447842 -0.0340059035652502 0.0054899194346409"
      rpy="0 0 0" />
    <parent
      link="Elbow_Yaw_L_Link" />
    <child
      link="Wrist_FE_L_Link" />
    <axis
      xyz="0.273256490871751 0.292390146216084 0.916427243479914" />
    <limit
      lower="-0.785"
      upper="0.785"
      effort="0"
      velocity="0" />
  </joint>
  <link
    name="Wrist_AA_L_Link">
    <inertial>
      <origin
        xyz="0.0481548139056346 -0.0885981643123183 0.0118544030044484"
        rpy="0 0 0" />
      <mass
        value="1.16294975479698" />
      <inertia
        ixx="0.0027861287011637"
        ixy="0.000655307459832117"
        ixz="4.65043904076585E-05"
        iyy="0.00150104013596433"
        iyz="5.68759630419156E-05"
        izz="0.00243451886071042" />
    </inertial>
    <visual>
      <origin
        xyz="0 0 0"
        rpy="0 0 0" />
      <geometry>
        <mesh
          filename="../meshes/Wrist_AA_L_Link.STL" />
      </geometry>
      <material
        name="">
        <color
          rgba="0.898039215686275 0.917647058823529 0.929411764705882 1" />
      </material>
    </visual>
    <collision>
      <origin
        xyz="0 0 0"
        rpy="0 0 0" />
      <geometry>
        <mesh
          filename="../meshes/Wrist_AA_L_Link.STL" />
      </geometry>
    </collision>
  </link>
  <joint
    name="Wrist_AA_L"
    type="revolute">
    <origin
      xyz="0.0439503306817846 -0.0831455976437052 0.0134230408415163"
      rpy="0 0 0" />
    <parent
      link="Wrist_FE_L_Link" />
    <child
      link="Wrist_AA_L_Link" />
    <axis
      xyz="0.843385849793954 0.385361551153234 -0.374428609029951" />
    <limit
      lower="-0.785"
      upper="0.785"
      effort="0"
      velocity="0" />
  </joint>
  <link
    name="Hip_Yaw_R_Link">
    <inertial>
      <origin
        xyz="0.0578410845121096 0.0820008286384128 -0.0573035744011938"
        rpy="0 0 0" />
      <mass
        value="1.87267545353134" />
      <inertia
        ixx="0.00289173144955821"
        ixy="0.000158739707429429"
        ixz="-0.00023483997255851"
        iyy="0.00300480416177858"
        iyz="-0.000332931872688091"
        izz="0.00307978274984304" />
    </inertial>
    <visual>
      <origin
        xyz="0 0 0"
        rpy="0 0 0" />
      <geometry>
        <mesh
          filename="../meshes/Hip_Yaw_R_Link.STL" />
      </geometry>
      <material
        name="">
        <color
          rgba="0.898039215686275 0.917647058823529 0.929411764705882 1" />
      </material>
    </visual>
    <collision>
      <origin
        xyz="0 0 0"
        rpy="0 0 0" />
      <geometry>
        <mesh
          filename="../meshes/Hip_Yaw_R_Link.STL" />
      </geometry>
    </collision>
  </link>
  <joint
    name="Hip_Yaw_R"
    type="revolute">
    <origin
      xyz="-0.18292 0 0.77669"
      rpy="1.5708 0 0" />
    <parent
      link="base_link" />
    <child
      link="Hip_Yaw_R_Link" />
    <axis
      xyz="0.5764 0.81716 0" />
    <limit
      lower="-0.785"
      upper="0.785"
      effort="0"
      velocity="0" />
  </joint>
  <link
    name="Hip_AA_R_Link">
    <inertial>
      <origin
        xyz="-2.69449785483822E-07 -0.0646115391941415 -0.000652188468069115"
        rpy="0 0 0" />
      <mass
        value="2.48825418562765" />
      <inertia
        ixx="0.00405037749012707"
        ixy="-3.5961153665738E-10"
        ixz="1.09319966244474E-10"
        iyy="0.00315132056134294"
        iyz="0.000500461315147233"
        izz="0.00387167610683285" />
    </inertial>
    <visual>
      <origin
        xyz="0 0 0"
        rpy="0 0 0" />
      <geometry>
        <mesh
          filename="../meshes/Hip_AA_R_Link.STL" />
      </geometry>
      <material
        name="">
        <color
          rgba="0.898039215686275 0.917647058823529 0.929411764705882 1" />
      </material>
    </visual>
    <collision>
      <origin
        xyz="0 0 0"
        rpy="0 0 0" />
      <geometry>
        <mesh
          filename="../meshes/Hip_AA_R_Link.STL" />
      </geometry>
    </collision>
  </link>
  <joint
    name="Hip_AA_R"
    type="revolute">
    <origin
      xyz="0.0481955931563164 0.0683264972269815 0"
      rpy="0 0 0" />
    <parent
      link="Hip_Yaw_R_Link" />
    <child
      link="Hip_AA_R_Link" />
    <axis
      xyz="0 0 1" />
    <limit
      lower="-0.785"
      upper="0.785"
      effort="0"
      velocity="0" />
  </joint>
  <link
    name="Leg_Yaw_R_Link">
    <inertial>
      <origin
        xyz="6.82227077608566E-09 -0.104403452809299 2.66533504267152E-15"
        rpy="0 0 0" />
      <mass
        value="4.0914725794956" />
      <inertia
        ixx="0.0142533854053674"
        ixy="1.49951509217404E-09"
        ixz="-6.16086353110232E-08"
        iyy="0.00576969016759821"
        iyz="5.78352776779898E-16"
        izz="0.0137448181862327" />
    </inertial>
    <visual>
      <origin
        xyz="0 0 0"
        rpy="0 0 0" />
      <geometry>
        <mesh
          filename="../meshes/Leg_Yaw_R_Link.STL" />
      </geometry>
      <material
        name="">
        <color
          rgba="0.898039215686275 0.917647058823529 0.929411764705882 1" />
      </material>
    </visual>
    <collision>
      <origin
        xyz="0 0 0"
        rpy="0 0 0" />
      <geometry>
        <mesh
          filename="../meshes/Leg_Yaw_R_Link.STL" />
      </geometry>
    </collision>
  </link>
  <joint
    name="Leg_Yaw_R"
    type="revolute">
    <origin
      xyz="0 -0.13 0"
      rpy="0 0 0" />
    <parent
      link="Hip_AA_R_Link" />
    <child
      link="Leg_Yaw_R_Link" />
    <axis
      xyz="0 1 0" />
    <limit
      lower="-0.785"
      upper="0.785"
      effort="0"
      velocity="0" />
  </joint>
  <link
    name="Knee_FE_R_Link">
    <inertial>
      <origin
        xyz="-4.93987460936651E-08 -0.1303798261204 0.00432722001694677"
        rpy="0 0 0" />
      <mass
        value="3.40975209875335" />
      <inertia
        ixx="0.0524465518071102"
        ixy="7.02934990367548E-09"
        ixz="-8.46637666448873E-09"
        iyy="0.00511985305384163"
        iyz="0.000894089614904236"
        izz="0.0535345160267601" />
    </inertial>
    <visual>
      <origin
        xyz="0 0 0"
        rpy="0 0 0" />
      <geometry>
        <mesh
          filename="../meshes/Knee_FE_R_Link.STL" />
      </geometry>
      <material
        name="">
        <color
          rgba="0.898039215686275 0.917647058823529 0.929411764705882 1" />
      </material>
    </visual>
    <collision>
      <origin
        xyz="0 0 0"
        rpy="0 0 0" />
      <geometry>
        <mesh
          filename="../meshes/Knee_FE_R_Link.STL" />
      </geometry>
    </collision>
  </link>
  <joint
    name="Knee_FE_R"
    type="revolute">
    <origin
      xyz="0 -0.195911086202374 0"
      rpy="0 0 0" />
    <parent
      link="Leg_Yaw_R_Link" />
    <child
      link="Knee_FE_R_Link" />
    <axis
      xyz="1 0 0" />
    <limit
      lower="-2.094"
      upper="0"
      effort="0"
      velocity="0" />
  </joint>
  <link
    name="Ankle_FE_R_Link">
    <inertial>
      <origin
        xyz="2.13230261780772E-08 -3.31102187334231E-10 1.73086544095303E-08"
        rpy="0 0 0" />
      <mass
        value="0.153834925462232" />
      <inertia
        ixx="4.48755162014596E-05"
        ixy="-1.14948613513671E-12"
        ixz="-1.49200435840691E-11"
        iyy="4.91482585618936E-05"
        iyz="2.31778812055718E-11"
        izz="3.14808463200294E-05" />
    </inertial>
    <visual>
      <origin
        xyz="0 0 0"
        rpy="0 0 0" />
      <geometry>
        <mesh
          filename="../meshes/Ankle_FE_R_Link.STL" />
      </geometry>
      <material
        name="">
        <color
          rgba="0.898039215686275 0.917647058823529 0.929411764705882 1" />
      </material>
    </visual>
    <collision>
      <origin
        xyz="0 0 0"
        rpy="0 0 0" />
      <geometry>
        <mesh
          filename="../meshes/Ankle_FE_R_Link.STL" />
      </geometry>
    </collision>
  </link>
  <joint
    name="Ankle_FE_R"
    type="revolute">
    <origin
      xyz="0 -0.399106992412679 0"
      rpy="0 0 0" />
    <parent
      link="Knee_FE_R_Link" />
    <child
      link="Ankle_FE_R_Link" />
    <axis
      xyz="1 0 0" />
    <limit
      lower="-0.785"
      upper="0.785"
      effort="0"
      velocity="0" />
  </joint>
  <link
    name="Ankle_AA_R_Link">
    <inertial>
      <origin
        xyz="4.70497521498636E-09 -0.0888982973512883 0.0475242006785333"
        rpy="0 0 0" />
      <mass
        value="2.13461169422066" />
      <inertia
        ixx="0.00890209560798504"
        ixy="-3.02319429852812E-10"
        ixz="-3.31335378706138E-11"
        iyy="0.0083072021840268"
        iyz="0.000961558978902551"
        izz="0.00188215989143463" />
    </inertial>
    <visual>
      <origin
        xyz="0 0 0"
        rpy="0 0 0" />
      <geometry>
        <mesh
          filename="../meshes/Ankle_AA_R_Link.STL" />
      </geometry>
      <material
        name="">
        <color
          rgba="0.898039215686275 0.917647058823529 0.929411764705882 1" />
      </material>
    </visual>
    <collision>
      <origin
        xyz="0 0 0"
        rpy="0 0 0" />
      <geometry>
        <mesh
          filename="../meshes/Ankle_AA_R_Link.STL" />
      </geometry>
    </collision>
  </link>
  <joint
    name="Ankle_AA_R"
    type="revolute">
    <origin
      xyz="0 0 0"
      rpy="0 0 0" />
    <parent
      link="Ankle_FE_R_Link" />
    <child
      link="Ankle_AA_R_Link" />
    <axis
      xyz="0 0 1" />
    <limit
      lower="-0.785"
      upper="0.785"
      effort="0"
      velocity="0" />
  </joint>
  <link
    name="Hip_Yaw_L_Link">
    <inertial>
      <origin
        xyz="0 0 0"
        rpy="0 0 0" />
      <mass
        value="0" />
      <inertia
        ixx="0"
        ixy="0"
        ixz="0"
        iyy="0"
        iyz="0"
        izz="0" />
    </inertial>
    <visual>
      <origin
        xyz="0 0 0"
        rpy="0 0 0" />
      <geometry>
        <mesh
          filename="../meshes/Hip_Yaw_L_Link.STL" />
      </geometry>
      <material
        name="">
        <color
          rgba="1 1 1 1" />
      </material>
    </visual>
    <collision>
      <origin
        xyz="0 0 0"
        rpy="0 0 0" />
      <geometry>
        <mesh
          filename="../meshes/Hip_Yaw_L_Link.STL" />
      </geometry>
    </collision>
  </link>
  <joint
    name="Hip_Yaw_L"
    type="revolute">
    <origin
      xyz="0.130955787324032 0 0.850357317544145"
      rpy="1.5707963267949 0 0" />
    <parent
      link="base_link" />
    <child
      link="Hip_Yaw_L_Link" />
    <axis
      xyz="0.576404776244777 -0.817164324920152 0" />
    <limit
      lower="-0.785"
      upper="0.785"
      effort="0"
      velocity="0" />
  </joint>
  <link
    name="Hip_AA_L_Link">
    <inertial>
      <origin
        xyz="-2.62266962453017E-07 -0.0646116873978295 -0.000652066625577265"
        rpy="0 0 0" />
      <mass
        value="2.48825113860261" />
      <inertia
        ixx="0.00405037803146433"
        ixy="-2.08780618374345E-09"
        ixz="3.17730270187968E-09"
        iyy="0.00315132204448699"
        iyz="0.000500459479043544"
        izz="0.00387166959773019" />
    </inertial>
    <visual>
      <origin
        xyz="0 0 0"
        rpy="0 0 0" />
      <geometry>
        <mesh
          filename="../meshes/Hip_AA_L_Link.STL" />
      </geometry>
      <material
        name="">
        <color
          rgba="0.898039215686275 0.917647058823529 0.929411764705882 1" />
      </material>
    </visual>
    <collision>
      <origin
        xyz="0 0 0"
        rpy="0 0 0" />
      <geometry>
        <mesh
          filename="../meshes/Hip_AA_L_Link.STL" />
      </geometry>
    </collision>
  </link>
  <joint
    name="Hip_AA_L"
    type="revolute">
    <origin
      xyz="0.00376614926323537 -0.00533923892909116 0"
      rpy="0 0 0" />
    <parent
      link="Hip_Yaw_L_Link" />
    <child
      link="Hip_AA_L_Link" />
    <axis
      xyz="0 0 1" />
    <limit
      lower="-0.785"
      upper="0.785"
      effort="0"
      velocity="0" />
  </joint>
  <link
    name="Leg_Yaw_L_Link">
    <inertial>
      <origin
        xyz="6.82227951909198E-09 -0.104403445541586 4.68211355669955E-15"
        rpy="0 0 0" />
      <mass
        value="4.09147176216603" />
      <inertia
        ixx="0.0142533811399932"
        ixy="1.47594001631118E-09"
        ixz="-5.88046718179431E-08"
        iyy="0.00576969008395192"
        iyz="1.68085727330861E-16"
        izz="0.013744816339507" />
    </inertial>
    <visual>
      <origin
        xyz="0 0 0"
        rpy="0 0 0" />
      <geometry>
        <mesh
          filename="../meshes/Leg_Yaw_L_Link.STL" />
      </geometry>
      <material
        name="">
        <color
          rgba="0.898039215686275 0.917647058823529 0.929411764705882 1" />
      </material>
    </visual>
    <collision>
      <origin
        xyz="0 0 0"
        rpy="0 0 0" />
      <geometry>
        <mesh
          filename="../meshes/Leg_Yaw_L_Link.STL" />
      </geometry>
    </collision>
  </link>
  <joint
    name="Leg_Yaw_L"
    type="revolute">
    <origin
      xyz="0 -0.13 0"
      rpy="0 0 0" />
    <parent
      link="Hip_AA_L_Link" />
    <child
      link="Leg_Yaw_L_Link" />
    <axis
      xyz="0 1 0" />
    <limit
      lower="-0.785"
      upper="0.785"
      effort="0"
      velocity="0" />
  </joint>
  <link
    name="Knee_FE_L_Link">
    <inertial>
      <origin
        xyz="-0.00198284083556183 -0.132387821786023 0.00461322617281429"
        rpy="0 0 0" />
      <mass
        value="3.19835325034246" />
      <inertia
        ixx="0.0523532579591458"
        ixy="-6.44161322043689E-09"
        ixz="8.32602353989091E-09"
        iyy="0.00503890138177925"
        iyz="0.000894090531679506"
        izz="0.0534535657648782" />
    </inertial>
    <visual>
      <origin
        xyz="0 0 0"
        rpy="0 0 0" />
      <geometry>
        <mesh
          filename="../meshes/Knee_FE_L_Link.STL" />
      </geometry>
      <material
        name="">
        <color
          rgba="0.898039215686275 0.917647058823529 0.929411764705882 1" />
      </material>
    </visual>
    <collision>
      <origin
        xyz="0 0 0"
        rpy="0 0 0" />
      <geometry>
        <mesh
          filename="../meshes/Knee_FE_L_Link.STL" />
      </geometry>
    </collision>
  </link>
  <joint
    name="Knee_FE_L"
    type="revolute">
    <origin
      xyz="0 -0.195911086202374 0"
      rpy="0 0 0" />
    <parent
      link="Leg_Yaw_L_Link" />
    <child
      link="Knee_FE_L_Link" />
    <axis
      xyz="1 0 0" />
    <limit
      lower="-2.094"
      upper="0"
      effort="0"
      velocity="0" />
  </joint>
  <link
    name="Ankle_FE_L_Link">
    <inertial>
      <origin
        xyz="-2.15278271042951E-08 -6.91215279458035E-11 1.80190664845847E-08"
        rpy="0 0 0" />
      <mass
        value="0.153834949413743" />
      <inertia
        ixx="4.48755211744641E-05"
        ixy="4.29871081789534E-13"
        ixz="1.2901438273711E-11"
        iyy="4.91482963109345E-05"
        iyz="1.29232571260581E-10"
        izz="3.1480829846544E-05" />
    </inertial>
    <visual>
      <origin
        xyz="0 0 0"
        rpy="0 0 0" />
      <geometry>
        <mesh
          filename="../meshes/Ankle_FE_L_Link.STL" />
      </geometry>
      <material
        name="">
        <color
          rgba="0.898039215686275 0.917647058823529 0.929411764705882 1" />
      </material>
    </visual>
    <collision>
      <origin
        xyz="0 0 0"
        rpy="0 0 0" />
      <geometry>
        <mesh
          filename="../meshes/Ankle_FE_L_Link.STL" />
      </geometry>
    </collision>
  </link>
  <joint
    name="Ankle_FE_L"
    type="revolute">
    <origin
      xyz="0 -0.399106992412679 0"
      rpy="0 0 0" />
    <parent
      link="Knee_FE_L_Link" />
    <child
      link="Ankle_FE_L_Link" />
    <axis
      xyz="1 0 0" />
    <limit
      lower="-0.785"
      upper="0.785"
      effort="0"
      velocity="0" />
  </joint>
  <link
    name="Ankle_AA_L_Link">
    <inertial>
      <origin
        xyz="-1.44560177717246E-08 -0.0888983146151464 0.0475241817527442"
        rpy="0 0 0" />
      <mass
        value="2.13461028514175" />
      <inertia
        ixx="0.0089020907103915"
        ixy="6.35895615377347E-10"
        ixz="1.03567266094569E-09"
        iyy="0.00830719794466869"
        iyz="0.000961559759681165"
        izz="0.00188215837469731" />
    </inertial>
    <visual>
      <origin
        xyz="0 0 0"
        rpy="0 0 0" />
      <geometry>
        <mesh
          filename="../meshes/Ankle_AA_L_Link.STL" />
      </geometry>
      <material
        name="">
        <color
          rgba="0.898039215686275 0.917647058823529 0.929411764705882 1" />
      </material>
    </visual>
    <collision>
      <origin
        xyz="0 0 0"
        rpy="0 0 0" />
      <geometry>
        <mesh
          filename="../meshes/Ankle_AA_L_Link.STL" />
      </geometry>
    </collision>
  </link>
  <joint
    name="Ankle_AA_L"
    type="revolute">
    <origin
      xyz="0 0 0"
      rpy="0 0 0" />
    <parent
      link="Ankle_FE_L_Link" />
    <child
      link="Ankle_AA_L_Link" />
    <axis
      xyz="0 0 1" />
    <limit
      lower="-0.785"
      upper="0.785"
      effort="0"
      velocity="0" />
  </joint>
</robot>